<?xml version="1.0" encoding="UTF-8"?>
<testng-results skipped="0" failed="1" ignored="0" total="2" passed="1">
  <reporter-output>
  </reporter-output>
  <suite name="Suite" duration-ms="4868" started-at="2018-08-30T09:16:47Z" finished-at="2018-08-30T09:16:52Z">
    <groups>
    </groups>
    <test name="ValidateTitleTest" duration-ms="3379" started-at="2018-08-30T09:16:47Z" finished-at="2018-08-30T09:16:51Z">
      <class name="qmetry.ValidateTitleTest">
        <test-method status="PASS" signature="validateTitle()[pri:0, instance:qmetry.ValidateTitleTest@6a1aab78]" name="validateTitle" duration-ms="3345" started-at="2018-08-30T09:16:47Z" finished-at="2018-08-30T09:16:51Z">
          <reporter-output>
          </reporter-output>
        </test-method> <!-- validateTitle -->
      </class> <!-- qmetry.ValidateTitleTest -->
    </test> <!-- ValidateTitleTest -->
    <test name="ValidateLoginTest" duration-ms="1445" started-at="2018-08-30T09:16:51Z" finished-at="2018-08-30T09:16:52Z">
      <class name="qmetry.ValidateLoginTest">
        <test-method status="FAIL" signature="validateLogin()[pri:0, instance:qmetry.ValidateLoginTest@78ac1102]" name="validateLogin" duration-ms="1438" started-at="2018-08-30T09:16:51Z" finished-at="2018-08-30T09:16:52Z">
          <exception class="java.lang.AssertionError">
            <message>
              <![CDATA[expected [true] but found [false]]]>
            </message>
            <full-stacktrace>
              <![CDATA[java.lang.AssertionError: expected [true] but found [false]
at org.testng.Assert.fail(Assert.java:96)
at org.testng.Assert.failNotEquals(Assert.java:776)
at org.testng.Assert.assertTrue(Assert.java:44)
at org.testng.Assert.assertTrue(Assert.java:54)
at qmetry.ValidateLoginTest.validateLogin(ValidateLoginTest.java:24)
at sun.reflect.NativeMethodAccessorImpl.invoke0(Native Method)
at sun.reflect.NativeMethodAccessorImpl.invoke(Unknown Source)
at sun.reflect.DelegatingMethodAccessorImpl.invoke(Unknown Source)
at java.lang.reflect.Method.invoke(Unknown Source)
at org.testng.internal.MethodInvocationHelper.invokeMethod(MethodInvocationHelper.java:124)
at org.testng.internal.Invoker.invokeMethod(Invoker.java:580)
at org.testng.internal.Invoker.invokeTestMethod(Invoker.java:716)
at org.testng.internal.Invoker.invokeTestMethods(Invoker.java:988)
at org.testng.internal.TestMethodWorker.invokeTestMethods(TestMethodWorker.java:125)
at org.testng.internal.TestMethodWorker.run(TestMethodWorker.java:109)
at org.testng.TestRunner.privateRun(TestRunner.java:648)
at org.testng.TestRunner.run(TestRunner.java:505)
at org.testng.SuiteRunner.runTest(SuiteRunner.java:455)
at org.testng.SuiteRunner.runSequentially(SuiteRunner.java:450)
at org.testng.SuiteRunner.privateRun(SuiteRunner.java:415)
at org.testng.SuiteRunner.run(SuiteRunner.java:364)
at org.testng.SuiteRunnerWorker.runSuite(SuiteRunnerWorker.java:52)
at org.testng.SuiteRunnerWorker.run(SuiteRunnerWorker.java:84)
at org.testng.TestNG.runSuitesSequentially(TestNG.java:1208)
at org.testng.TestNG.runSuitesLocally(TestNG.java:1137)
at org.testng.TestNG.runSuites(TestNG.java:1049)
at org.testng.TestNG.run(TestNG.java:1017)
at org.testng.remote.AbstractRemoteTestNG.run(AbstractRemoteTestNG.java:114)
at org.testng.remote.RemoteTestNG.initAndRun(RemoteTestNG.java:251)
at org.testng.remote.RemoteTestNG.main(RemoteTestNG.java:77)
]]>
            </full-stacktrace>
          </exception> <!-- java.lang.AssertionError -->
          <reporter-output>
          </reporter-output>
        </test-method> <!-- validateLogin -->
      </class> <!-- qmetry.ValidateLoginTest -->
    </test> <!-- ValidateLoginTest -->
  </suite> <!-- Suite -->
</testng-results>
